Traceback (most recent call last):
  File "c:\users\ignac\anaconda3\envs\mlfenv\lib\site-packages\nbclient\client.py", line 622, in _async_poll_for_reply
    msg = await ensure_async(self.kc.shell_channel.get_msg(timeout=new_timeout))
  File "c:\users\ignac\anaconda3\envs\mlfenv\lib\site-packages\nbclient\util.py", line 85, in ensure_async
    result = await obj
  File "c:\users\ignac\anaconda3\envs\mlfenv\lib\site-packages\jupyter_client\asynchronous\channels.py", line 48, in get_msg
    raise Empty
queue.Empty

During handling of the above exception, another exception occurred:

Traceback (most recent call last):
  File "c:\users\ignac\anaconda3\envs\mlfenv\lib\site-packages\jupyter_cache\executors\utils.py", line 56, in single_nb_execution
    record_timing=False,
  File "c:\users\ignac\anaconda3\envs\mlfenv\lib\site-packages\nbclient\client.py", line 1112, in execute
    return NotebookClient(nb=nb, resources=resources, km=km, **kwargs).execute()
  File "c:\users\ignac\anaconda3\envs\mlfenv\lib\site-packages\nbclient\util.py", line 74, in wrapped
    return just_run(coro(*args, **kwargs))
  File "c:\users\ignac\anaconda3\envs\mlfenv\lib\site-packages\nbclient\util.py", line 53, in just_run
    return loop.run_until_complete(coro)
  File "c:\users\ignac\anaconda3\envs\mlfenv\lib\asyncio\base_events.py", line 488, in run_until_complete
    return future.result()
  File "c:\users\ignac\anaconda3\envs\mlfenv\lib\site-packages\nbclient\client.py", line 554, in async_execute
    cell, index, execution_count=self.code_cells_executed + 1
  File "c:\users\ignac\anaconda3\envs\mlfenv\lib\site-packages\nbclient\client.py", line 841, in async_execute_cell
    exec_reply = await self.task_poll_for_reply
  File "c:\users\ignac\anaconda3\envs\mlfenv\lib\site-packages\nbclient\client.py", line 646, in _async_poll_for_reply
    await self._async_handle_timeout(timeout, cell)
  File "c:\users\ignac\anaconda3\envs\mlfenv\lib\site-packages\nbclient\client.py", line 697, in _async_handle_timeout
    "Cell execution timed out", timeout, cell
nbclient.exceptions.CellTimeoutError: A cell timed out while it was being executed, after 30 seconds.
The message was: Cell execution timed out.
Here is a preview of the cell contents:
-------------------
['num_sim = 1000', 'trajs = []', 'np.random.seed(0)', 'torch.manual_seed(0)', 't_0 = time.time()']
...
['    # end the loop over time steps', '    trajs.append(this_traj)', '    returns_all.append(returns_array)', '', "print('Done simulating trajectories in %f sec'% (time.time() - t_0))"]
-------------------

